<?xml version="1.0" encoding="UTF-8"?>
<!-- Generated by org.testng.reporters.JUnitReportReporter -->
<testsuite skipped="0" hostname="Aditya-Laptop" name="com.sample.practice.DataStr.MyListTest" tests="3" failures="0" timestamp="07 Jun 2018 11:21:30 GMT" time="0.050" errors="2">
  <testcase name="testList" time="0.035" classname="com.sample.practice.DataStr.MyListTest"/>
  <testcase name="testNegative" time="0.007" classname="com.sample.practice.DataStr.MyListTest">
    <error type="org.testng.TestException" message="
Method MyListTest.testNegative()[pri:0, instance:com.sample.practice.DataStr.MyListTest@55f3ddb1] should have thrown an exception of type class java.lang.IndexOutOfBoundsException">
      <![CDATA[org.testng.TestException: 
Method MyListTest.testNegative()[pri:0, instance:com.sample.practice.DataStr.MyListTest@55f3ddb1] should have thrown an exception of type class java.lang.IndexOutOfBoundsException
	at org.testng.internal.ExpectedExceptionsHolder.noException(ExpectedExceptionsHolder.java:89)
	at org.testng.internal.Invoker.handleInvocationResults(Invoker.java:1416)
	at org.testng.internal.Invoker.invokeMethod(Invoker.java:695)
	at org.testng.internal.Invoker.invokeTestMethod(Invoker.java:869)
	at org.testng.internal.Invoker.invokeTestMethods(Invoker.java:1193)
	at org.testng.internal.TestMethodWorker.invokeTestMethods(TestMethodWorker.java:126)
	at org.testng.internal.TestMethodWorker.run(TestMethodWorker.java:109)
	at org.testng.TestRunner.privateRun(TestRunner.java:744)
	at org.testng.TestRunner.run(TestRunner.java:602)
	at org.testng.SuiteRunner.runTest(SuiteRunner.java:380)
	at org.testng.SuiteRunner.runSequentially(SuiteRunner.java:375)
	at org.testng.SuiteRunner.privateRun(SuiteRunner.java:340)
	at org.testng.SuiteRunner.run(SuiteRunner.java:289)
	at org.testng.SuiteRunnerWorker.runSuite(SuiteRunnerWorker.java:52)
	at org.testng.SuiteRunnerWorker.run(SuiteRunnerWorker.java:86)
	at org.testng.TestNG.runSuitesSequentially(TestNG.java:1301)
	at org.testng.TestNG.runSuitesLocally(TestNG.java:1226)
	at org.testng.TestNG.runSuites(TestNG.java:1144)
	at org.testng.TestNG.run(TestNG.java:1115)
	at org.testng.remote.AbstractRemoteTestNG.run(AbstractRemoteTestNG.java:114)
	at org.testng.remote.RemoteTestNG.initAndRun(RemoteTestNG.java:251)
	at org.testng.remote.RemoteTestNG.main(RemoteTestNG.java:77)
]]>
    </error>
  </testcase> <!-- testNegative -->
  <testcase name="testMyList" time="0.008" classname="com.sample.practice.DataStr.MyListTest">
    <error type="org.testng.TestException" message="
Method MyListTest.testMyList()[pri:0, instance:com.sample.practice.DataStr.MyListTest@55f3ddb1] should have thrown an exception of type class java.lang.IndexOutOfBoundsException">
      <![CDATA[org.testng.TestException: 
Method MyListTest.testMyList()[pri:0, instance:com.sample.practice.DataStr.MyListTest@55f3ddb1] should have thrown an exception of type class java.lang.IndexOutOfBoundsException
	at org.testng.internal.ExpectedExceptionsHolder.noException(ExpectedExceptionsHolder.java:89)
	at org.testng.internal.Invoker.handleInvocationResults(Invoker.java:1416)
	at org.testng.internal.Invoker.invokeMethod(Invoker.java:695)
	at org.testng.internal.Invoker.invokeTestMethod(Invoker.java:869)
	at org.testng.internal.Invoker.invokeTestMethods(Invoker.java:1193)
	at org.testng.internal.TestMethodWorker.invokeTestMethods(TestMethodWorker.java:126)
	at org.testng.internal.TestMethodWorker.run(TestMethodWorker.java:109)
	at org.testng.TestRunner.privateRun(TestRunner.java:744)
	at org.testng.TestRunner.run(TestRunner.java:602)
	at org.testng.SuiteRunner.runTest(SuiteRunner.java:380)
	at org.testng.SuiteRunner.runSequentially(SuiteRunner.java:375)
	at org.testng.SuiteRunner.privateRun(SuiteRunner.java:340)
	at org.testng.SuiteRunner.run(SuiteRunner.java:289)
	at org.testng.SuiteRunnerWorker.runSuite(SuiteRunnerWorker.java:52)
	at org.testng.SuiteRunnerWorker.run(SuiteRunnerWorker.java:86)
	at org.testng.TestNG.runSuitesSequentially(TestNG.java:1301)
	at org.testng.TestNG.runSuitesLocally(TestNG.java:1226)
	at org.testng.TestNG.runSuites(TestNG.java:1144)
	at org.testng.TestNG.run(TestNG.java:1115)
	at org.testng.remote.AbstractRemoteTestNG.run(AbstractRemoteTestNG.java:114)
	at org.testng.remote.RemoteTestNG.initAndRun(RemoteTestNG.java:251)
	at org.testng.remote.RemoteTestNG.main(RemoteTestNG.java:77)
]]>
    </error>
  </testcase> <!-- testMyList -->
</testsuite> <!-- com.sample.practice.DataStr.MyListTest -->
